[2025-03-11T13:01:12.451+0100] {taskinstance.py:1956} INFO - Dependencies all met for dep_context=non-requeueable deps ti=<TaskInstance: postgres_etl_dag.transform_and_load manual__2025-03-11T12:01:10.752855+00:00 [queued]>
[2025-03-11T13:01:12.458+0100] {taskinstance.py:1956} INFO - Dependencies all met for dep_context=requeueable deps ti=<TaskInstance: postgres_etl_dag.transform_and_load manual__2025-03-11T12:01:10.752855+00:00 [queued]>
[2025-03-11T13:01:12.458+0100] {taskinstance.py:2170} INFO - Starting attempt 1 of 1
[2025-03-11T13:01:12.468+0100] {taskinstance.py:2191} INFO - Executing <Task(PythonOperator): transform_and_load> on 2025-03-11 12:01:10.752855+00:00
[2025-03-11T13:01:12.472+0100] {standard_task_runner.py:60} INFO - Started process 268399 to run task
[2025-03-11T13:01:12.475+0100] {standard_task_runner.py:87} INFO - Running: ['airflow', 'tasks', 'run', 'postgres_etl_dag', 'transform_and_load', 'manual__2025-03-11T12:01:10.752855+00:00', '--job-id', '43', '--raw', '--subdir', 'DAGS_FOLDER/first.py', '--cfg-path', '/tmp/tmpg2xcu7z1']
[2025-03-11T13:01:12.478+0100] {standard_task_runner.py:88} INFO - Job 43: Subtask transform_and_load
[2025-03-11T13:01:12.537+0100] {task_command.py:423} INFO - Running <TaskInstance: postgres_etl_dag.transform_and_load manual__2025-03-11T12:01:10.752855+00:00 [running]> on host LAPTOP-A4DHQTS9.
[2025-03-11T13:01:12.611+0100] {taskinstance.py:2480} INFO - Exporting env vars: AIRFLOW_CTX_DAG_OWNER='airflow' AIRFLOW_CTX_DAG_ID='postgres_etl_dag' AIRFLOW_CTX_TASK_ID='transform_and_load' AIRFLOW_CTX_EXECUTION_DATE='2025-03-11T12:01:10.752855+00:00' AIRFLOW_CTX_TRY_NUMBER='1' AIRFLOW_CTX_DAG_RUN_ID='manual__2025-03-11T12:01:10.752855+00:00'
[2025-03-11T13:01:12.623+0100] {base.py:83} INFO - Using connection ID 'postgres_source' for task execution.
[2025-03-11T13:01:12.629+0100] {sql.py:450} INFO - Running statement: select * from "s_table";
    , parameters: None
[2025-03-11T13:01:12.630+0100] {taskinstance.py:2698} ERROR - Task failed with exception
Traceback (most recent call last):
  File "/home/philip/de_engineering/airflow_projects/airflow1/venv/lib/python3.10/site-packages/airflow/models/taskinstance.py", line 433, in _execute_task
    result = execute_callable(context=context, **execute_callable_kwargs)
  File "/home/philip/de_engineering/airflow_projects/airflow1/venv/lib/python3.10/site-packages/airflow/operators/python.py", line 199, in execute
    return_value = self.execute_callable()
  File "/home/philip/de_engineering/airflow_projects/airflow1/venv/lib/python3.10/site-packages/airflow/operators/python.py", line 216, in execute_callable
    return self.python_callable(*self.op_args, **self.op_kwargs)
  File "/home/philip/airflow/dags/first.py", line 31, in transform_data
    extracted_data = windows_hook.get_records(sql)
  File "/home/philip/de_engineering/airflow_projects/airflow1/venv/lib/python3.10/site-packages/airflow/providers/common/sql/hooks/sql.py", line 261, in get_records
    return self.run(sql=sql, parameters=parameters, handler=fetch_all_handler)
  File "/home/philip/de_engineering/airflow_projects/airflow1/venv/lib/python3.10/site-packages/airflow/providers/common/sql/hooks/sql.py", line 398, in run
    self._run_command(cur, sql_statement, parameters)
  File "/home/philip/de_engineering/airflow_projects/airflow1/venv/lib/python3.10/site-packages/airflow/providers/common/sql/hooks/sql.py", line 455, in _run_command
    cur.execute(sql_statement)
psycopg2.errors.UndefinedTable: relation "s_table" does not exist
LINE 1: select * from "s_table";
                      ^

[2025-03-11T13:01:12.642+0100] {taskinstance.py:1138} INFO - Marking task as FAILED. dag_id=postgres_etl_dag, task_id=transform_and_load, execution_date=20250311T120110, start_date=20250311T120112, end_date=20250311T120112
[2025-03-11T13:01:12.651+0100] {standard_task_runner.py:107} ERROR - Failed to execute job 43 for task transform_and_load (relation "s_table" does not exist
LINE 1: select * from "s_table";
                      ^
; 268399)
[2025-03-11T13:01:12.692+0100] {local_task_job_runner.py:234} INFO - Task exited with return code 1
[2025-03-11T13:01:12.708+0100] {taskinstance.py:3280} INFO - 0 downstream tasks scheduled from follow-on schedule check
