[2025-03-11T12:46:19.077+0100] {taskinstance.py:1956} INFO - Dependencies all met for dep_context=non-requeueable deps ti=<TaskInstance: postgres_etl_dag.transform_and_load manual__2025-03-11T11:46:15.833881+00:00 [queued]>
[2025-03-11T12:46:19.084+0100] {taskinstance.py:1956} INFO - Dependencies all met for dep_context=requeueable deps ti=<TaskInstance: postgres_etl_dag.transform_and_load manual__2025-03-11T11:46:15.833881+00:00 [queued]>
[2025-03-11T12:46:19.084+0100] {taskinstance.py:2170} INFO - Starting attempt 1 of 1
[2025-03-11T12:46:19.096+0100] {taskinstance.py:2191} INFO - Executing <Task(PythonOperator): transform_and_load> on 2025-03-11 11:46:15.833881+00:00
[2025-03-11T12:46:19.098+0100] {standard_task_runner.py:60} INFO - Started process 265171 to run task
[2025-03-11T12:46:19.101+0100] {standard_task_runner.py:87} INFO - Running: ['airflow', 'tasks', 'run', 'postgres_etl_dag', 'transform_and_load', 'manual__2025-03-11T11:46:15.833881+00:00', '--job-id', '35', '--raw', '--subdir', 'DAGS_FOLDER/first.py', '--cfg-path', '/tmp/tmpkih8urpu']
[2025-03-11T12:46:19.102+0100] {standard_task_runner.py:88} INFO - Job 35: Subtask transform_and_load
[2025-03-11T12:46:19.154+0100] {task_command.py:423} INFO - Running <TaskInstance: postgres_etl_dag.transform_and_load manual__2025-03-11T11:46:15.833881+00:00 [running]> on host LAPTOP-A4DHQTS9.
[2025-03-11T12:46:19.244+0100] {taskinstance.py:2480} INFO - Exporting env vars: AIRFLOW_CTX_DAG_OWNER='airflow' AIRFLOW_CTX_DAG_ID='postgres_etl_dag' AIRFLOW_CTX_TASK_ID='transform_and_load' AIRFLOW_CTX_EXECUTION_DATE='2025-03-11T11:46:15.833881+00:00' AIRFLOW_CTX_TRY_NUMBER='1' AIRFLOW_CTX_DAG_RUN_ID='manual__2025-03-11T11:46:15.833881+00:00'
[2025-03-11T12:46:19.257+0100] {base.py:83} INFO - Using connection ID 'postgres_source' for task execution.
[2025-03-11T12:46:19.265+0100] {sql.py:450} INFO - Running statement: select * from public.s_table;
    , parameters: None
[2025-03-11T12:46:19.267+0100] {taskinstance.py:2698} ERROR - Task failed with exception
Traceback (most recent call last):
  File "/home/philip/de_engineering/airflow_projects/airflow1/venv/lib/python3.10/site-packages/airflow/models/taskinstance.py", line 433, in _execute_task
    result = execute_callable(context=context, **execute_callable_kwargs)
  File "/home/philip/de_engineering/airflow_projects/airflow1/venv/lib/python3.10/site-packages/airflow/operators/python.py", line 199, in execute
    return_value = self.execute_callable()
  File "/home/philip/de_engineering/airflow_projects/airflow1/venv/lib/python3.10/site-packages/airflow/operators/python.py", line 216, in execute_callable
    return self.python_callable(*self.op_args, **self.op_kwargs)
  File "/home/philip/airflow/dags/first.py", line 31, in transform_data
    extracted_data = windows_hook.get_records(sql)
  File "/home/philip/de_engineering/airflow_projects/airflow1/venv/lib/python3.10/site-packages/airflow/providers/common/sql/hooks/sql.py", line 261, in get_records
    return self.run(sql=sql, parameters=parameters, handler=fetch_all_handler)
  File "/home/philip/de_engineering/airflow_projects/airflow1/venv/lib/python3.10/site-packages/airflow/providers/common/sql/hooks/sql.py", line 398, in run
    self._run_command(cur, sql_statement, parameters)
  File "/home/philip/de_engineering/airflow_projects/airflow1/venv/lib/python3.10/site-packages/airflow/providers/common/sql/hooks/sql.py", line 455, in _run_command
    cur.execute(sql_statement)
psycopg2.errors.UndefinedTable: relation "public.s_table" does not exist
LINE 1: select * from public.s_table;
                      ^

[2025-03-11T12:46:19.280+0100] {taskinstance.py:1138} INFO - Marking task as FAILED. dag_id=postgres_etl_dag, task_id=transform_and_load, execution_date=20250311T114615, start_date=20250311T114619, end_date=20250311T114619
[2025-03-11T12:46:19.292+0100] {standard_task_runner.py:107} ERROR - Failed to execute job 35 for task transform_and_load (relation "public.s_table" does not exist
LINE 1: select * from public.s_table;
                      ^
; 265171)
[2025-03-11T12:46:19.320+0100] {local_task_job_runner.py:234} INFO - Task exited with return code 1
[2025-03-11T12:46:19.336+0100] {taskinstance.py:3280} INFO - 0 downstream tasks scheduled from follow-on schedule check
