[2025-03-27T13:05:05.516+0100] {taskinstance.py:1956} INFO - Dependencies all met for dep_context=non-requeueable deps ti=<TaskInstance: test_dag.transfer_data manual__2025-03-27T12:05:02.065240+00:00 [queued]>
[2025-03-27T13:05:05.522+0100] {taskinstance.py:1956} INFO - Dependencies all met for dep_context=requeueable deps ti=<TaskInstance: test_dag.transfer_data manual__2025-03-27T12:05:02.065240+00:00 [queued]>
[2025-03-27T13:05:05.523+0100] {taskinstance.py:2170} INFO - Starting attempt 1 of 1
[2025-03-27T13:05:05.533+0100] {taskinstance.py:2191} INFO - Executing <Task(PythonOperator): transfer_data> on 2025-03-27 12:05:02.065240+00:00
[2025-03-27T13:05:05.535+0100] {standard_task_runner.py:60} INFO - Started process 5250 to run task
[2025-03-27T13:05:05.538+0100] {standard_task_runner.py:87} INFO - Running: ['airflow', 'tasks', 'run', 'test_dag', 'transfer_data', 'manual__2025-03-27T12:05:02.065240+00:00', '--job-id', '91', '--raw', '--subdir', 'DAGS_FOLDER/test_dag.py', '--cfg-path', '/tmp/tmpm4lcr0ci']
[2025-03-27T13:05:05.539+0100] {standard_task_runner.py:88} INFO - Job 91: Subtask transfer_data
[2025-03-27T13:05:05.585+0100] {task_command.py:423} INFO - Running <TaskInstance: test_dag.transfer_data manual__2025-03-27T12:05:02.065240+00:00 [running]> on host LAPTOP-A4DHQTS9.
[2025-03-27T13:05:05.662+0100] {taskinstance.py:2480} INFO - Exporting env vars: AIRFLOW_CTX_DAG_OWNER='airflow' AIRFLOW_CTX_DAG_ID='test_dag' AIRFLOW_CTX_TASK_ID='transfer_data' AIRFLOW_CTX_EXECUTION_DATE='2025-03-27T12:05:02.065240+00:00' AIRFLOW_CTX_TRY_NUMBER='1' AIRFLOW_CTX_DAG_RUN_ID='manual__2025-03-27T12:05:02.065240+00:00'
[2025-03-27T13:05:05.674+0100] {base.py:83} INFO - Using connection ID 'source_db' for task execution.
[2025-03-27T13:05:05.680+0100] {sql.py:450} INFO - Running statement: SELECT * FROM prog3;, parameters: None
[2025-03-27T13:05:05.682+0100] {sql.py:459} INFO - Rows affected: 30
[2025-03-27T13:05:05.691+0100] {base.py:83} INFO - Using connection ID 'destination_db' for task execution.
[2025-03-27T13:05:05.710+0100] {taskinstance.py:2698} ERROR - Task failed with exception
Traceback (most recent call last):
  File "/home/philip/de_engineering/airflow_projects/airflow1/venv/lib/python3.10/site-packages/airflow/models/taskinstance.py", line 433, in _execute_task
    result = execute_callable(context=context, **execute_callable_kwargs)
  File "/home/philip/de_engineering/airflow_projects/airflow1/venv/lib/python3.10/site-packages/airflow/operators/python.py", line 199, in execute
    return_value = self.execute_callable()
  File "/home/philip/de_engineering/airflow_projects/airflow1/venv/lib/python3.10/site-packages/airflow/operators/python.py", line 216, in execute_callable
    return self.python_callable(*self.op_args, **self.op_kwargs)
  File "/home/philip/airflow/dags/test_dag.py", line 68, in transfer_data
    dest_pg_hook.insert_rows(f"staging.{destination_table}", source_data)
  File "/home/philip/de_engineering/airflow_projects/airflow1/venv/lib/python3.10/site-packages/airflow/providers/common/sql/hooks/sql.py", line 541, in insert_rows
    cur.execute(sql, values)
psycopg2.errors.UndefinedTable: missing FROM-clause entry for table "new"
LINE 2:          VALUES (NEW.uid, NEW.lastupdated, NEW."Area (H)", N...
                         ^
QUERY:  INSERT INTO transformation.tr_prog3 (uid, lastupdated, "Area (H)", farmers) 
         VALUES (NEW.uid, NEW.lastupdated, NEW."Area (H)", NEW.farmers)
         ON CONFLICT (uid) 
         DO UPDATE SET "Area (H)" = EXCLUDED."Area (H)", farmers = EXCLUDED.farmers 
         WHERE transformation.lastupdated < EXCLUDED.lastupdated;
CONTEXT:  PL/pgSQL function utils.update_transformation_table() line 47 at EXECUTE

[2025-03-27T13:05:05.722+0100] {taskinstance.py:1138} INFO - Marking task as FAILED. dag_id=test_dag, task_id=transfer_data, execution_date=20250327T120502, start_date=20250327T120505, end_date=20250327T120505
[2025-03-27T13:05:05.729+0100] {standard_task_runner.py:107} ERROR - Failed to execute job 91 for task transfer_data (missing FROM-clause entry for table "new"
LINE 2:          VALUES (NEW.uid, NEW.lastupdated, NEW."Area (H)", N...
                         ^
QUERY:  INSERT INTO transformation.tr_prog3 (uid, lastupdated, "Area (H)", farmers) 
         VALUES (NEW.uid, NEW.lastupdated, NEW."Area (H)", NEW.farmers)
         ON CONFLICT (uid) 
         DO UPDATE SET "Area (H)" = EXCLUDED."Area (H)", farmers = EXCLUDED.farmers 
         WHERE transformation.lastupdated < EXCLUDED.lastupdated;
CONTEXT:  PL/pgSQL function utils.update_transformation_table() line 47 at EXECUTE
; 5250)
[2025-03-27T13:05:05.751+0100] {local_task_job_runner.py:234} INFO - Task exited with return code 1
[2025-03-27T13:05:05.765+0100] {taskinstance.py:3280} INFO - 0 downstream tasks scheduled from follow-on schedule check
