[2025-03-26T12:14:03.743+0100] {taskinstance.py:1956} INFO - Dependencies all met for dep_context=non-requeueable deps ti=<TaskInstance: test_dag.transfer_data scheduled__2025-03-25T00:00:00+00:00 [queued]>
[2025-03-26T12:14:03.750+0100] {taskinstance.py:1956} INFO - Dependencies all met for dep_context=requeueable deps ti=<TaskInstance: test_dag.transfer_data scheduled__2025-03-25T00:00:00+00:00 [queued]>
[2025-03-26T12:14:03.750+0100] {taskinstance.py:2170} INFO - Starting attempt 1 of 1
[2025-03-26T12:14:03.761+0100] {taskinstance.py:2191} INFO - Executing <Task(PythonOperator): transfer_data> on 2025-03-25 00:00:00+00:00
[2025-03-26T12:14:03.764+0100] {standard_task_runner.py:60} INFO - Started process 36194 to run task
[2025-03-26T12:14:03.766+0100] {standard_task_runner.py:87} INFO - Running: ['airflow', 'tasks', 'run', 'test_dag', 'transfer_data', 'scheduled__2025-03-25T00:00:00+00:00', '--job-id', '51', '--raw', '--subdir', 'DAGS_FOLDER/test_dag.py', '--cfg-path', '/tmp/tmpbw932xen']
[2025-03-26T12:14:03.768+0100] {standard_task_runner.py:88} INFO - Job 51: Subtask transfer_data
[2025-03-26T12:14:03.817+0100] {task_command.py:423} INFO - Running <TaskInstance: test_dag.transfer_data scheduled__2025-03-25T00:00:00+00:00 [running]> on host LAPTOP-A4DHQTS9.
[2025-03-26T12:14:03.879+0100] {taskinstance.py:2480} INFO - Exporting env vars: AIRFLOW_CTX_DAG_OWNER='airflow' AIRFLOW_CTX_DAG_ID='test_dag' AIRFLOW_CTX_TASK_ID='transfer_data' AIRFLOW_CTX_EXECUTION_DATE='2025-03-25T00:00:00+00:00' AIRFLOW_CTX_TRY_NUMBER='1' AIRFLOW_CTX_DAG_RUN_ID='scheduled__2025-03-25T00:00:00+00:00'
[2025-03-26T12:14:03.888+0100] {base.py:83} INFO - Using connection ID 'source_db' for task execution.
[2025-03-26T12:14:03.894+0100] {sql.py:450} INFO - Running statement: SELECT * FROM prog3;, parameters: None
[2025-03-26T12:14:03.900+0100] {taskinstance.py:2698} ERROR - Task failed with exception
Traceback (most recent call last):
  File "/home/philip/de_engineering/airflow_projects/airflow1/venv/lib/python3.10/site-packages/airflow/models/taskinstance.py", line 433, in _execute_task
    result = execute_callable(context=context, **execute_callable_kwargs)
  File "/home/philip/de_engineering/airflow_projects/airflow1/venv/lib/python3.10/site-packages/airflow/operators/python.py", line 199, in execute
    return_value = self.execute_callable()
  File "/home/philip/de_engineering/airflow_projects/airflow1/venv/lib/python3.10/site-packages/airflow/operators/python.py", line 216, in execute_callable
    return self.python_callable(*self.op_args, **self.op_kwargs)
  File "/home/philip/airflow/dags/test_dag.py", line 59, in transfer_data
    source_data = src_pg_hook.get_records(extract_query)  # Fetch data
  File "/home/philip/de_engineering/airflow_projects/airflow1/venv/lib/python3.10/site-packages/airflow/providers/common/sql/hooks/sql.py", line 261, in get_records
    return self.run(sql=sql, parameters=parameters, handler=fetch_all_handler)
  File "/home/philip/de_engineering/airflow_projects/airflow1/venv/lib/python3.10/site-packages/airflow/providers/common/sql/hooks/sql.py", line 398, in run
    self._run_command(cur, sql_statement, parameters)
  File "/home/philip/de_engineering/airflow_projects/airflow1/venv/lib/python3.10/site-packages/airflow/providers/common/sql/hooks/sql.py", line 455, in _run_command
    cur.execute(sql_statement)
psycopg2.errors.InsufficientPrivilege: permission denied for view prog3

[2025-03-26T12:14:03.912+0100] {taskinstance.py:1138} INFO - Marking task as FAILED. dag_id=test_dag, task_id=transfer_data, execution_date=20250325T000000, start_date=20250326T111403, end_date=20250326T111403
[2025-03-26T12:14:03.922+0100] {standard_task_runner.py:107} ERROR - Failed to execute job 51 for task transfer_data (permission denied for view prog3
; 36194)
[2025-03-26T12:14:03.940+0100] {local_task_job_runner.py:234} INFO - Task exited with return code 1
[2025-03-26T12:14:03.954+0100] {taskinstance.py:3280} INFO - 0 downstream tasks scheduled from follow-on schedule check
