[2025-03-10T13:41:57.262+0100] {taskinstance.py:1956} INFO - Dependencies all met for dep_context=non-requeueable deps ti=<TaskInstance: postgres_etl_dag.transform_and_load manual__2025-03-10T12:36:53.946752+00:00 [queued]>
[2025-03-10T13:41:57.269+0100] {taskinstance.py:1956} INFO - Dependencies all met for dep_context=requeueable deps ti=<TaskInstance: postgres_etl_dag.transform_and_load manual__2025-03-10T12:36:53.946752+00:00 [queued]>
[2025-03-10T13:41:57.269+0100] {taskinstance.py:2170} INFO - Starting attempt 2 of 2
[2025-03-10T13:41:57.279+0100] {taskinstance.py:2191} INFO - Executing <Task(PythonOperator): transform_and_load> on 2025-03-10 12:36:53.946752+00:00
[2025-03-10T13:41:57.282+0100] {standard_task_runner.py:60} INFO - Started process 199470 to run task
[2025-03-10T13:41:57.285+0100] {standard_task_runner.py:87} INFO - Running: ['airflow', 'tasks', 'run', 'postgres_etl_dag', 'transform_and_load', 'manual__2025-03-10T12:36:53.946752+00:00', '--job-id', '16', '--raw', '--subdir', 'DAGS_FOLDER/first.py', '--cfg-path', '/tmp/tmp63g0huyj']
[2025-03-10T13:41:57.287+0100] {standard_task_runner.py:88} INFO - Job 16: Subtask transform_and_load
[2025-03-10T13:41:57.342+0100] {task_command.py:423} INFO - Running <TaskInstance: postgres_etl_dag.transform_and_load manual__2025-03-10T12:36:53.946752+00:00 [running]> on host LAPTOP-A4DHQTS9.
[2025-03-10T13:41:57.416+0100] {taskinstance.py:2480} INFO - Exporting env vars: AIRFLOW_CTX_DAG_OWNER='airflow' AIRFLOW_CTX_DAG_ID='postgres_etl_dag' AIRFLOW_CTX_TASK_ID='transform_and_load' AIRFLOW_CTX_EXECUTION_DATE='2025-03-10T12:36:53.946752+00:00' AIRFLOW_CTX_TRY_NUMBER='2' AIRFLOW_CTX_DAG_RUN_ID='manual__2025-03-10T12:36:53.946752+00:00'
[2025-03-10T13:41:57.429+0100] {base.py:83} INFO - Using connection ID 'postgres_source' for task execution.
[2025-03-10T13:41:57.435+0100] {taskinstance.py:2698} ERROR - Task failed with exception
Traceback (most recent call last):
  File "/home/philip/de_engineering/airflow_projects/airflow1/venv/lib/python3.10/site-packages/airflow/models/taskinstance.py", line 433, in _execute_task
    result = execute_callable(context=context, **execute_callable_kwargs)
  File "/home/philip/de_engineering/airflow_projects/airflow1/venv/lib/python3.10/site-packages/airflow/operators/python.py", line 199, in execute
    return_value = self.execute_callable()
  File "/home/philip/de_engineering/airflow_projects/airflow1/venv/lib/python3.10/site-packages/airflow/operators/python.py", line 216, in execute_callable
    return self.python_callable(*self.op_args, **self.op_kwargs)
  File "/home/philip/airflow/dags/first.py", line 29, in transform_data
    extracted_data = windows_hook.get_records("SELECT * FROM source_;")
  File "/home/philip/de_engineering/airflow_projects/airflow1/venv/lib/python3.10/site-packages/airflow/providers/common/sql/hooks/sql.py", line 261, in get_records
    return self.run(sql=sql, parameters=parameters, handler=fetch_all_handler)
  File "/home/philip/de_engineering/airflow_projects/airflow1/venv/lib/python3.10/site-packages/airflow/providers/common/sql/hooks/sql.py", line 391, in run
    with closing(self.get_conn()) as conn:
  File "/home/philip/de_engineering/airflow_projects/airflow1/venv/lib/python3.10/site-packages/airflow/providers/postgres/hooks/postgres.py", line 158, in get_conn
    self.conn = psycopg2.connect(**conn_args)
  File "/home/philip/de_engineering/airflow_projects/airflow1/venv/lib/python3.10/site-packages/psycopg2/__init__.py", line 122, in connect
    conn = _connect(dsn, connection_factory=connection_factory, **kwasync)
psycopg2.OperationalError: connection to server at "127.0.0.1", port 5432 failed: FATAL:  database "test_database" does not exist

[2025-03-10T13:41:57.447+0100] {taskinstance.py:1138} INFO - Marking task as FAILED. dag_id=postgres_etl_dag, task_id=transform_and_load, execution_date=20250310T123653, start_date=20250310T124157, end_date=20250310T124157
[2025-03-10T13:41:57.457+0100] {standard_task_runner.py:107} ERROR - Failed to execute job 16 for task transform_and_load (connection to server at "127.0.0.1", port 5432 failed: FATAL:  database "test_database" does not exist
; 199470)
[2025-03-10T13:41:57.467+0100] {local_task_job_runner.py:234} INFO - Task exited with return code 1
[2025-03-10T13:41:57.488+0100] {taskinstance.py:3280} INFO - 0 downstream tasks scheduled from follow-on schedule check
